Workbook

Sheet Dados_Brasil
A1: rank | B1: Youtuber | C1: subscribers | D1: video views | E1: category | F1: uploads | G1: Country | H1: channel_type | I1: video_views_for_the_last_30_days | J1: lowest_monthly_earnings | K1: highest_monthly_earnings | L1: lowest_yearly_earnings | M1: highest_yearly_earnings | N1: created_date | O1: Views_por_Inscrito | P1: Receita_Media_Mensal | Q1: Tamanho_Canal | R1: Inscritos_por_Video | S1: CPM_por_Milhao | T1: Momentum_Percentual | U1: Anos_no_YouTube | V1: Classificacao_BCG
A2: 1 | B2: Canal KondZilla | C2: 66500000 | D2: 36775585925 | E2: Music | F2: 2572 | G2: Brazil | H2: Music | I2: 447223000 | J2: 0 | K2: 0 | L2: 0 | M2: 0 | N2: 40989 | O2: =D2/C2 -> 553.01633 | P2: =(J2+K2)/2 -> 0 | Q2: =IF(C2>=10000000,"Mega",IF(C2>=1000000,"Grande",IF(C2>=100000,"Médio","Pequeno"))) -> Mega | R2: =C2/F2 -> 25855.365 | S2: =(P2/I2)*1000000 -> 0 | T2: =I2/D2 -> 0.012160867 | U2: =2023-YEAR(N2) -> 11 | V2: =IF(AND(O2>AVERAGE($O$2:$O$58),T2>AVERAGE($T$2:$T$58)),"⭐ ESTRELA",IF(AND(O2>AVERAGE($O$2:$O$58),T2<=AVERAGE($T$2:$T$58)),"🐄 VACA LEITEIRA",IF(AND(O2<=AVERAGE($O$2:$O$58),T2>AVERAGE($T$2:$T$58)),"❓ INTERROGAÇÃO","🐕 EVITAR"))) -> 🐄 VACA LEITEIRA
A3: 2 | B3: Felipe Neto | C3: 45200000 | D3: 16602198273 | E3: Entertainment | F3: 4331 | G3: Brazil | H3: Entertainment | I3: 130359000 | J3: 32600 | K3: 521400 | L3: 391100 | M3: 6300000 | N3: 38853 | O3: =D3/C3 -> 367.30527 | P3: =(J3+K3)/2 -> 277000 | Q3: =IF(C3>=10000000,"Mega",IF(C3>=1000000,"Grande",IF(C3>=100000,"Médio","Pequeno"))) -> Mega | R3: =C3/F3 -> 10436.389 | S3: =(P3/I3)*1000000 -> 2124.9012 | T3: =I3/D3 -> 0.007851912 | U3: =2023-YEAR(N3) -> 17 | V3: =IF(AND(O3>AVERAGE($O$2:$O$58),T3>AVERAGE($T$2:$T$58)),"⭐ ESTRELA",IF(AND(O3>AVERAGE($O$2:$O$58),T3<=AVERAGE($T$2:$T$58)),"🐄 VACA LEITEIRA",IF(AND(O3<=AVERAGE($O$2:$O$58),T3>AVERAGE($T$2:$T$58)),"❓ INTERROGAÇÃO","🐕 EVITAR"))) -> 🐕 EVITAR
A4: 3 | B4: Você Sabia? | C4: 44700000 | D4: 7828610828 | E4: Entertainment | F4: 1558 | G4: Brazil | H4: Entertainment | I4: 48032000 | J4: 12000 | K4: 192100 | L4: 144100 | M4: 2300000 | N4: 41518 | O4: =D4/C4 -> 175.13671 | P4: =(J4+K4)/2 -> 102050 | Q4: =IF(C4>=10000000,"Mega",IF(C4>=1000000,"Grande",IF(C4>=100000,"Médio","Pequeno"))) -> Mega | R4: =C4/F4 -> 28690.629 | S4: =(P4/I4)*1000000 -> 2124.6253 | T4: =I4/D4 -> 0.0061354436 | U4: =2023-YEAR(N4) -> 10 | V4: =IF(AND(O4>AVERAGE($O$2:$O$58),T4>AVERAGE($T$2:$T$58)),"⭐ ESTRELA",IF(AND(O4>AVERAGE($O$2:$O$58),T4<=AVERAGE($T$2:$T$58)),"🐄 VACA LEITEIRA",IF(AND(O4<=AVERAGE($O$2:$O$58),T4>AVERAGE($T$2:$T$58)),"❓ INTERROGAÇÃO","🐕 EVITAR"))) -> 🐕 EVITAR
A5: 4 | B5: whindersson nunes | C5: 44200000 | D5: 4274709210 | E5: Comedy | F5: 558 | G5: Brazil | H5: Comedy | I5: 26683000 | J5: 6700 | K5: 106700 | L5: 80100 | M5: 1300000 | N5: 41295 | O5: =D5/C5 -> 96.712878 | P5: =(J5+K5)/2 -> 56700 | Q5: =IF(C5>=10000000,"Mega",IF(C5>=1000000,"Grande",IF(C5>=100000,"Médio","Pequeno"))) -> Mega | R5: =C5/F5 -> 79211.47 | S5: =(P5/I5)*1000000 -> 2124.9485 | T5: =I5/D5 -> 0.006242062 | U5: =2023-YEAR(N5) -> 10 | V5: =IF(AND(O5>AVERAGE($O$2:$O$58),T5>AVERAGE($T$2:$T$58)),"⭐ ESTRELA",IF(AND(O5>AVERAGE($O$2:$O$58),T5<=AVERAGE($T$2:$T$58)),"🐄 VACA LEITEIRA",IF(AND(O5<=AVERAGE($O$2:$O$58),T5>AVERAGE($T$2:$T$58)),"❓ INTERROGAÇÃO","🐕 EVITAR"))) -> 🐕 EVITAR
A6: 6 | B6: GR6 EXPLODE | C6: 38900000 | D6: 25154232306 | E6: Music | F6: 3043 | G6: Brazil | H6: Music | I6: 1635000000 | J6: 408700 | K6: 6500000 | L6: 4900000 | M6: 78500000 | N6: 41856 | O6: =D6/C6 -> 646.63836 | P6: =(J6+K6)/2 -> 3454350 | Q6: =IF(C6>=10000000,"Mega",IF(C6>=1000000,"Grande",IF(C6>=100000,"Médio","Pequeno"))) -> Mega | R6: =C6/F6 -> 12783.437 | S6: =(P6/I6)*1000000 -> 2112.7523 | T6: =I6/D6 -> 0.064999002 | U6: =2023-YEAR(N6) -> 9 | V6: =IF(AND(O6>AVERAGE($O$2:$O$58),T6>AVERAGE($T$2:$T$58)),"⭐ ESTRELA",IF(AND(O6>AVERAGE($O$2:$O$58),T6<=AVERAGE($T$2:$T$58)),"🐄 VACA LEITEIRA",IF(AND(O6<=AVERAGE($O$2:$O$58),T6>AVERAGE($T$2:$T$58)),"❓ INTERROGAÇÃO","🐕 EVITAR"))) -> ⭐ ESTRELA
A7: 7 | B7: Maria Clara & JP | C7: 37000000 | D7: 24188861917 | E7: People & Blogs | F7: 744 | G7: Brazil | H7: Entertainment | I7: 251449000 | J7: 62900 | K7: 1000000 | L7: 754300 | M7: 12100000 | N7: 42253 | O7: =D7/C7 -> 653.75302 | P7: =(J7+K7)/2 -> 531450 | Q7: =IF(C7>=10000000,"Mega",IF(C7>=1000000,"Grande",IF(C7>=100000,"Médio","Pequeno"))) -> Mega | R7: =C7/F7 -> 49731.183 | S7: =(P7/I7)*1000000 -> 2113.5499 | T7: =I7/D7 -> 0.010395239 | U7: =2023-YEAR(N7) -> 8 | V7: =IF(AND(O7>AVERAGE($O$2:$O$58),T7>AVERAGE($T$2:$T$58)),"⭐ ESTRELA",IF(AND(O7>AVERAGE($O$2:$O$58),T7<=AVERAGE($T$2:$T$58)),"🐄 VACA LEITEIRA",IF(AND(O7<=AVERAGE($O$2:$O$58),T7>AVERAGE($T$2:$T$58)),"❓ INTERROGAÇÃO","🐕 EVITAR"))) -> 🐄 VACA LEITEIRA
A8: 8 | B8: Galinha Pintadinha | C8: 33800000 | D8: 27274550757 | E8: Film & Animation | F8: 66 | G8: Brazil | H8: Film | I8: 403508000 | J8: 100900 | K8: 1600000 | L8: 1200000 | M8: 19400000 | N8: 38959 | O8: =D8/C8 -> 806.93937 | P8: =(J8+K8)/2 -> 850450 | Q8: =IF(C8>=10000000,"Mega",IF(C8>=1000000,"Grande",IF(C8>=100000,"Médio","Pequeno"))) -> Mega | R8: =C8/F8 -> 512121.21 | S8: =(P8/I8)*1000000 -> 2107.641 | T8: =I8/D8 -> 0.014794304 | U8: =2023-YEAR(N8) -> 17 | V8: =IF(AND(O8>AVERAGE($O$2:$O$58),T8>AVERAGE($T$2:$T$58)),"⭐ ESTRELA",IF(AND(O8>AVERAGE($O$2:$O$58),T8<=AVERAGE($T$2:$T$58)),"🐄 VACA LEITEIRA",IF(AND(O8<=AVERAGE($O$2:$O$58),T8>AVERAGE($T$2:$T$58)),"❓ INTERROGAÇÃO","🐕 EVITAR"))) -> ⭐ ESTRELA
A9: 9 | B9: rezende evil | C9: 32100000 | D9: 13061739758 | E9: Gaming | F9: 11882 | G9: Brazil | H9: Entertainment | I9: 44505000 | J9: 11100 | K9: 178000 | L9: 133500 | M9: 2100000 | N9: 40951 | O9: =D9/C9 -> 406.90778 | P9: =(J9+K9)/2 -> 94550 | Q9: =IF(C9>=10000000,"Mega",IF(C9>=1000000,"Grande",IF(C9>=100000,"Médio","Pequeno"))) -> Mega | R9: =C9/F9 -> 2701.5654 | S9: =(P9/I9)*1000000 -> 2124.4804 | T9: =I9/D9 -> 0.0034072796 | U9: =2023-YEAR(N9) -> 11 | V9: =IF(AND(O9>AVERAGE($O$2:$O$58),T9>AVERAGE($T$2:$T$58)),"⭐ ESTRELA",IF(AND(O9>AVERAGE($O$2:$O$58),T9<=AVERAGE($T$2:$T$58)),"🐄 VACA LEITEIRA",IF(AND(O9<=AVERAGE($O$2:$O$58),T9>AVERAGE($T$2:$T$58)),"❓ INTERROGAÇÃO","🐕 EVITAR"))) -> 🐄 VACA LEITEIRA
A10: 10 | B10: Enaldinho | C10: 29200000 | D10: 11627437847 | E10: Comedy | F10: 3654 | G10: Brazil | H10: Games | I10: 303100000 | J10: 75800 | K10: 1200000 | L10: 909300 | M10: 14500000 | N10: 40925 | O10: =D10/C10 -> 398.19993 | P10: =(J10+K10)/2 -> 637900 | Q10: =IF(C10>=10000000,"Mega",IF(C10>=1000000,"Grande",IF(C10>=100000,"Médio","Pequeno"))) -> Mega | R10: =C10/F10 -> 7991.2425 | S10: =(P10/I10)*1000000 -> 2104.5859 | T10: =I10/D10 -> 0.026067652 | U10: =2023-YEAR(N10) -> 11 | V10: =IF(AND(O10>AVERAGE($O$2:$O$58),T10>AVERAGE($T$2:$T$58)),"⭐ ESTRELA",IF(AND(O10>AVERAGE($O$2:$O$58),T10<=AVERAGE($T$2:$T$58)),"🐄 VACA LEITEIRA",IF(AND(O10<=AVERAGE($O$2:$O$58),T10>AVERAGE($T$2:$T$58)),"❓ INTERROGAÇÃO","🐕 EVITAR"))) -> ⭐ ESTRELA
A11: 11 | B11: Renato Garcia YT | C11: 26900000 | D11: 7938616641 | E11: Entertainment | F11: 3956 | G11: Brazil | H11: Entertainment | I11: 82912000 | J11: 20700 | K11: 331600 | L11: 248700 | M11: 4000000 | N11: 40815 | O11: =D11/C11 -> 295.11586 | P11: =(J11+K11)/2 -> 176150 | Q11: =IF(C11>=10000000,"Mega",IF(C11>=1000000,"Grande",IF(C11>=100000,"Médio","Pequeno"))) -> Mega | R11: =C11/F11 -> 6799.7978 | S11: =(P11/I11)*1000000 -> 2124.5417 | T11: =I11/D11 -> 0.010444137 | U11: =2023-YEAR(N11) -> 12 | V11: =IF(AND(O11>AVERAGE($O$2:$O$58),T11>AVERAGE($T$2:$T$58)),"⭐ ESTRELA",IF(AND(O11>AVERAGE($O$2:$O$58),T11<=AVERAGE($T$2:$T$58)),"🐄 VACA LEITEIRA",IF(AND(O11<=AVERAGE($O$2:$O$58),T11>AVERAGE($T$2:$T$58)),"❓ INTERROGAÇÃO","🐕 EVITAR"))) -> 🐕 EVITAR
A12: 13 | B12: Spider Slack | C12: 24000000 | D12: 13943030228 | E12: Comedy | F12: 901 | G12: Brazil | H12: Comedy | I12: 761451000 | J12: 190400 | K12: 3000000 | L12: 2300000 | M12: 36500000 | N12: 43969 | O12: =D12/C12 -> 580.95959 | P12: =(J12+K12)/2 -> 1595200 | Q12: =IF(C12>=10000000,"Mega",IF(C12>=1000000,"Grande",IF(C12>=100000,"Médio","Pequeno"))) -> Mega | R12: =C12/F12 -> 26637.07 | S12: =(P12/I12)*1000000 -> 2094.9477 | T12: =I12/D12 -> 0.054611586 | U12: =2023-YEAR(N12) -> 3 | V12: =IF(AND(O12>AVERAGE($O$2:$O$58),T12>AVERAGE($T$2:$T$58)),"⭐ ESTRELA",IF(AND(O12>AVERAGE($O$2:$O$58),T12<=AVERAGE($T$2:$T$58)),"🐄 VACA LEITEIRA",IF(AND(O12<=AVERAGE($O$2:$O$58),T12>AVERAGE($T$2:$T$58)),"❓ INTERROGAÇÃO","🐕 EVITAR"))) -> ⭐ ESTRELA
A13: 14 | B13: Valentina Pontes ofc | C13: 23400000 | D13: 7926899136 | E13: Film & Animation | F13: 1291 | G13: Brazil | H13: Entertainment | I13: 28285000 | J13: 7100 | K13: 113100 | L13: 84900 | M13: 1400000 | N13: 41743 | O13: =D13/C13 -> 338.75637 | P13: =(J13+K13)/2 -> 60100 | Q13: =IF(C13>=10000000,"Mega",IF(C13>=1000000,"Grande",IF(C13>=100000,"Médio","Pequeno"))) -> Mega | R13: =C13/F13 -> 18125.484 | S13: =(P13/I13)*1000000 -> 2124.8011 | T13: =I13/D13 -> 0.0035682301 | U13: =2023-YEAR(N13) -> 9 | V13: =IF(AND(O13>AVERAGE($O$2:$O$58),T13>AVERAGE($T$2:$T$58)),"⭐ ESTRELA",IF(AND(O13>AVERAGE($O$2:$O$58),T13<=AVERAGE($T$2:$T$58)),"🐄 VACA LEITEIRA",IF(AND(O13<=AVERAGE($O$2:$O$58),T13>AVERAGE($T$2:$T$58)),"❓ INTERROGAÇÃO","🐕 EVITAR"))) -> 🐕 EVITAR
... A58: 55 | B58: Natan por Aí | C58: 12300000 | D58: 9029609749 | E58: Sports | F58: 1200 | G58: Brazil | H58: Entertainment | I58: 552513000 | J58: 138100 | K58: 2200000 | L58: 1700000 | M58: 26500000 | N58: 42778 | O58: =D58/C58 -> 734.11461 | P58: =(J58+K58)/2 -> 1169050 | Q58: =IF(C58>=10000000,"Mega",IF(C58>=1000000,"Grande",IF(C58>=100000,"Médio","Pequeno"))) -> Mega | R58: =C58/F58 -> 10250 | S58: =(P58/I58)*1000000 -> 2115.8778 | T58: =I58/D58 -> 0.061189023 | U58: =2023-YEAR(N58) -> 6 | V58: =IF(AND(O58>AVERAGE($O$2:$O$58),T58>AVERAGE($T$2:$T$58)),"⭐ ESTRELA",IF(AND(O58>AVERAGE($O$2:$O$58),T58<=AVERAGE($T$2:$T$58)),"🐄 VACA LEITEIRA",IF(AND(O58<=AVERAGE($O$2:$O$58),T58>AVERAGE($T$2:$T$58)),"❓ INTERROGAÇÃO","🐕 EVITAR"))) -> ⭐ ESTRELA

Sheet Resumo_Estatistico
A1: ═══════════════════════════════════════════════════════════════════ | B1: 🏆 TOP 10 CANAIS MAIS EFICIENTES
A2: ANÁLISE DE INFLUENCIADORES BRASILEIROS NO YOUTUBE | B2: Rank | C2: Canal | D2: Inscrito | E2: Vídeos | F2: Inscrito/ Vídeo
A3: ═══════════════════════════════════════════════════════════════════ | B3: 1 | C3: Galinha Pintadinha | D3: 33800000 | E3: 66 | F3: 512121.21
B4: 2 | C4: Matheus Yurley | D4: 12900000 | E4: 69 | F4: 186956.52
A5: 📊 VISÃO GERAL | B5: 3 | C5: Hungria Hip Hop | D5: 13100000 | E5: 73 | F5: 179452.05
B6: 4 | C6: Anitta | D6: 17200000 | E6: 138 | F6: 124637.68
A7: Total de Canais Analisados: | B7: 5 | C7: Totoy kids - Português | D7: 20400000 | E7: 206 | F7: 99029.126
A8: =COUNTA(Dados_Brasil!B2:B58) -> 57 | B8: 6 | C8: whindersson nunes | D8: 44200000 | E8: 558 | F8: 79211.47
B9: 7 | C9: Canal Canalha | D9: 20800000 | E9: 288 | F9: 72222.222
A10: Distribuição por Tamanho: | B10: 8 | C10: Maria Clara & JP | D10: 37000000 | E10: 744 | F10: 49731.183
A11: Mega (≥10M): | B11: 9 | C11: Mundo Bita | D11: 12500000 | E11: 253 | F11: 49407.115
A12: =COUNTIF(Dados_Brasil!Q2:Q58,"Mega") -> 57 | B12: 10 | C12: Gusttavo Lima Oficial | D12: 19900000 | E12: 416 | F12: 47836.538
A14: Grande (1-10M): | B14: ═════════════════════════════════════════════════════
A15: =COUNTIF(Dados_Brasil!Q2:Q58,"Grande") -> 0 | B15: 💰 ANÁLISE 2: CUSTO-BENEFÍCIO (CPM)
B16: ═════════════════════════════════════════════════════
A17: Médio (100K-1M):
A18: =COUNTIF(Dados_Brasil!Q2:Q58,"Médio") -> 0 | B18: Melhor CPM (mais barato):
B19: =MIN(Dados_Brasil!S2:S58) -> 0
A20: Pequeno (<100K):
A21: =COUNTIF(Dados_Brasil!Q2:Q58,"Pequeno") -> 0 | B21: Pior CPM (mais caro):
B22: =MAX(Dados_Brasil!S2:S58) -> 2133.3686
A24: 📈 INSCRITOS (SUBSCRIBERS) | B24: CPM Médio:
B25: =AVERAGE(Dados_Brasil!S2:S58) -> 2086.4087
A26: Soma Total de Inscritos:
A27: =SUM(Dados_Brasil!C2:C58) -> 1147700000 | B27: 🏆 TOP 10 MELHOR CUSTO-BENEFÍCIO
B28: Rank | C28: Canal | D28: CPM | E28: Receita Mensal | F28: Views 30 dias
A29: Média de Inscritos por Canal: | B29: 1 | C29: Canal KondZilla | D29: 0 | E29: 0 | F29: 447223000
A30: =AVERAGE(Dados_Brasil!C2:C58) -> 20135088 | B30: 2 | C30: Spider Slack | D30: 2094.9477 | E30: 1595200 | F30: 761451000
B31: 3 | C31: Enaldinho | D31: 2104.5859 | E31: 637900 | F31: 303100000
A32: Canal com Mais Inscritos: | B32: 4 | C32: Galinha Pintadinha | D32: 2107.641 | E32: 850450 | F32: 403508000
A33: =MAX(Dados_Brasil!C2:C58) -> 66500000 | B33: 5 | C33: GR6 EXPLODE | D33: 2112.7523 | E33: 3454350 | F33: 1635000000
B34: 6 | C34: Maria Clara & JP | D34: 2113.5499 | E34: 531450 | F34: 251449000
A35: Canal com Menos Inscritos: | B35: 7 | C35: Natan por Aí | D35: 2115.8778 | E35: 1169050 | F35: 552513000
A36: =MIN(Dados_Brasil!C2:C58) -> 12300000 | B36: 8 | C36: Parafernalha | D36: 2123.4982 | E36: 15200 | F36: 7158000
B37: 9 | C37: Everson Zoio | D37: 2123.6894 | E37: 6481.5 | F37: 3052000
A38: Mediana de Inscritos: | B38: 10 | C38: Planeta das Gêmeas | D38: 2123.8267 | E38: 22400 | F38: 10547000
A39: =MEDIAN(Dados_Brasil!C2:C58) -> 15900000
B40: ═════════════════════════════════════════════════════
B41: 🔥 ANÁLISE 3: MOMENTUM (CRESCIMENTO ATUAL)
A42: 👁️ VISUALIZAÇÕES (VIDEO VIEWS) | B42: ═════════════════════════════════════════════════════
...

Sheet Análise_por_Categoria
A15: ════════════════════════════════════════════════════
A16: 🎭 ANÁLISE 7: ESTRATÉGIA POR CATEGORIA
A17: ════════════════════════════════════════════════════
A19: (Preencha manualmente após ver a tabela dinâmica)
A21: 📊 CATEGORIA DOMINANTE:
A22: Entretenimento - 14 canais - 286.400.000 inscritos
A24: 💰 CATEGORIA MAIS LUCRATIVA:
A25: Esporte - Receita média: R$ 1.169.050
A27: 🎯 MELHOR CUSTO-BENEFÍCIO:
A28: Esporte - CPM médio: R$ 2.115,88
A30: 📈 MAIOR ENGAJAMENTO:
A31: Esporte - 734 views/inscrito
... A37: Music, Sports, Comedy, Autos & Vehicles, Gaming, Entertainment, Film & Animation - Apenas 10 canais competindo
